<?xml version="1.0" ?>
<robot name="mar_robot">

  <link name="base_link">
    <visual>
      <geometry>
        <box size="0.4 0.2 0.1"/>
      </geometry>
      <material name="blue"><color rgba="0 0 1 1"/></material>
    </visual>
    <collision>
      <geometry>
        <box size="0.4 0.2 0.1"/>
      </geometry>
    </collision>
    <inertial>
      <mass value="2.0"/>
      <inertia ixx="0.008" ixy="0.0" ixz="0.0" iyy="0.028" iyz="0.0" izz="0.033"/>
    </inertial>
  </link>

  <link name="left_wheel">
    <visual>
      <geometry><cylinder radius="0.06" length="0.04"/></geometry>
      <material name="black"><color rgba="0 0 0 1"/></material>
    </visual>
    <collision>
      <geometry><cylinder radius="0.06" length="0.04"/></geometry>
    </collision>
    <inertial><mass value="0.2"/><inertia ixx="0.0002" ixy="0" ixz="0" iyy="0.0002" iyz="0" izz="0.0003"/></inertial>
  </link>

  <joint name="left_wheel_joint" type="continuous">
    <parent link="base_link"/>
    <child link="left_wheel"/>
    <origin xyz="-0.1 0.12 -0.05" rpy="-1.5708 0 0"/>
    <axis xyz="0 0 1"/>
  </joint>

  <link name="right_wheel">
    <visual>
      <geometry><cylinder radius="0.06" length="0.04"/></geometry>
      <material name="black"/>
    </visual>
    <collision>
      <geometry><cylinder radius="0.06" length="0.04"/></geometry>
    </collision>
    <inertial><mass value="0.2"/><inertia ixx="0.0002" ixy="0" ixz="0" iyy="0.0002" iyz="0" izz="0.0003"/></inertial>
  </link>

  <joint name="right_wheel_joint" type="continuous">
    <parent link="base_link"/>
    <child link="right_wheel"/>
    <origin xyz="-0.1 -0.12 -0.05" rpy="-1.5708 0 0"/>
    <axis xyz="0 0 1"/>
  </joint>

  <link name="caster_wheel">
    <visual><geometry><sphere radius="0.04"/></geometry><material name="black"/></visual>
    <collision><geometry><sphere radius="0.04"/></geometry></collision>
    <inertial><mass value="0.1"/><inertia ixx="0.0001" ixy="0" ixz="0" iyy="0.0001" iyz="0" izz="0.0001"/></inertial>
  </link>

  <joint name="caster_joint" type="fixed">
    <parent link="base_link"/>
    <child link="caster_wheel"/>
    <origin xyz="0.15 0 -0.07" rpy="0 0 0"/>
  </joint>

  <link name="camera_link">
    <visual><geometry><box size="0.02 0.05 0.02"/></geometry><material name="red"><color rgba="1 0 0 1"/></material></visual>
  </link>
  <joint name="camera_joint" type="fixed">
    <parent link="base_link"/>
    <child link="camera_link"/>
    <origin xyz="0.2 0 0" rpy="0 1.5708 0"/> 
  </joint>

  <link name="lidar_link">
    <visual><geometry><cylinder radius="0.04" length="0.04"/></geometry><material name="black"/></visual>
  </link>
  <joint name="lidar_joint" type="fixed">
    <parent link="base_link"/>
    <child link="lidar_link"/>
    <origin xyz="0.15 0 0.07" rpy="0 0 0"/>
  </joint>

  <gazebo>
    <plugin name="diff_drive" filename="libgazebo_ros_diff_drive.so">
      <update_rate>30</update_rate>
      <left_joint>left_wheel_joint</left_joint>
      <right_joint>right_wheel_joint</right_joint>
      <wheel_separation>0.24</wheel_separation>
      <wheel_diameter>0.12</wheel_diameter>
      <max_wheel_torque>20</max_wheel_torque>
      <max_wheel_acceleration>1.0</max_wheel_acceleration>
      <publish_odom>true</publish_odom>
      <publish_odom_tf>true</publish_odom_tf>
      <publish_wheel_tf>true</publish_wheel_tf>
      <odometry_frame>odom</odometry_frame>
      <robot_base_frame>base_link</robot_base_frame>
    </plugin>
  </gazebo>

  <gazebo reference="camera_link">
    <sensor type="camera" name="robot_camera">
      <update_rate>30.0</update_rate>
      <camera name="head">
        <horizontal_fov>1.3962634</horizontal_fov>
        <image><width>640</width><height>480</height><format>R8G8B8</format></image>
        <clip><near>0.02</near><far>300</far></clip>
      </camera>
      <plugin name="camera_controller" filename="libgazebo_ros_camera.so">
        <alwaysOn>true</alwaysOn>
        <updateRate>0.0</updateRate>
        <cameraName>camera</cameraName>
        <imageTopicName>image_raw</imageTopicName>
        <cameraInfoTopicName>camera_info</cameraInfoTopicName>
        <frameName>camera_link</frameName>
      </plugin>
    </sensor>
  </gazebo>

  <gazebo reference="lidar_link">
    <sensor type="ray" name="robot_lidar">
      <pose>0 0 0 0 0 0</pose>
      <visualize>true</visualize>
      <update_rate>10</update_rate>
      <ray>
        <scan><horizontal><samples>360</samples><resolution>1</resolution><min_angle>-1.57</min_angle><max_angle>1.57</max_angle></horizontal></scan>
        <range><min>0.15</min><max>6.0</max><resolution>0.01</resolution></range>
      </ray>
      <plugin name="lidar_controller" filename="libgazebo_ros_ray_sensor.so">
        <ros><remapping>~/out:=scan</remapping></ros>
        <output_type>sensor_msgs/LaserScan</output_type>
        <frame_name>lidar_link</frame_name>
      </plugin>
    </sensor>
  </gazebo>
</robot>
